Workbook

Sheet Overwash_Matrix
A1: Hatteras Island Overwash Observation Matrix · 1984–2024
A2: HOW TO USE: Add one row per Google Earth imagery date you assess. The date shown in the bottom-left of Google Earth goes in 'Imagery_Date' (YYYY-MM-DD format). Year and Season auto-calculate. Enter 1 = overwash present · 0 = no overwash (you checked and it's clear) · leave BLANK = not assessed / imagery unusable. See 'Storm_Reference' sheet for dates of known storms to search for in Google Earth.
I3: Cape Point | O3: Buxton | Q3: Inter-village: Buxton–Avon | AC3: Avon | AN3: Inter-village: Avon–Tri-Village | BX3: Tri-Village | CN3: Pea Island / N. of Rodanthe
A4: Obs_ID | B4: Imagery_Date | C4: Year | D4: Season | E4: Linked_Event_ID | F4: Storm_Name | G4: Image_Quality | H4: Source | I4: 1 | J4: 2 | K4: 3 | L4: 4 | M4: 5 | N4: 6 | O4: 7 | P4: 8 | Q4: 9 | R4: 10 | S4: 11 | T4: 12 | U4: 13 | V4: 14 | W4: 15 | X4: 16 | Y4: 17 | Z4: 18 | AA4: 19 | AB4: 20 | AC4: 21 | AD4: 22 | AE4: 23 | AF4: 24 | AG4: 25 | AH4: 26 | AI4: 27 | AJ4: 28 | AK4: 29 | AL4: 30 | AM4: 31 | AN4: 32 | AO4: 33 | AP4: 34 | AQ4: 35 | AR4: 36 | AS4: 37 | AT4: 38 | AU4: 39 | AV4: 40 | AW4: 41 | AX4: 42 | AY4: 43 | AZ4: 44 | BA4: 45 | BB4: 46 | BC4: 47 | BD4: 48 | BE4: 49 | BF4: 50 | BG4: 51 | BH4: 52 | BI4: 53 | BJ4: 54 | BK4: 55 | BL4: 56 | BM4: 57 | BN4: 58 | BO4: 59 | BP4: 60 | BQ4: 61 | BR4: 62 | BS4: 63 | BT4: 64 | BU4: 65 | BV4: 66 | BW4: 67 | BX4: 68 | BY4: 69 | BZ4: 70 | CA4: 71 | CB4: 72 | CC4: 73 | CD4: 74 | CE4: 75 | CF4: 76 | CG4: 77 | CH4: 78 | CI4: 79 | CJ4: 80 | CK4: 81 | CL4: 82 | CM4: 83 | CN4: 84 | CO4: 85 | CP4: 86 | CQ4: 87 | CR4: 88 | CS4: 89 | CT4: 90
A5: OBS-001 | B5: 30944 | C5: =IF(B5="","",YEAR(B5)) -> 1984 | D5: =IF(B5="","",IF(MONTH(B5)<=2,"Winter",IF(MONTH(B5)<=5,"Spring",IF(MONTH(B5)<=8,"Summer","Fall")))) -> Fall | E5: STM-1984-DIA | F5: DIANA | H5: Hapke and Henderson | I5: 0 | J5: 0 | K5: 0 | L5: 0 | M5: 0 | N5: 0 | O5: 0 | P5: 0 | Q5: 0 | R5: 0 | S5: 0 | T5: 0 | U5: 0 | V5: 0 | W5: 0 | X5: 0 | Y5: 0 | Z5: 0 | AA5: 0 | AB5: 0 | AC5: 0 | AD5: 0 | AE5: 0 | AF5: 0 | AG5: 0 | AH5: 0 | AI5: 0 | AJ5: 0 | AK5: 0 | AL5: 0 | AM5: 0 | AN5: 0 | AO5: 0 | AP5: 0 | AQ5: 0 | AR5: 0 | AS5: 0 | AT5: 0 | AU5: 0 | AV5: 0 | AW5: 0 | AX5: 0 | AY5: 0 | AZ5: 0 | BA5: 0 | BB5: 0 | BC5: 0 | BD5: 0 | BE5: 0 | BF5: 0 | BG5: 0 | BH5: 0 | BI5: 0 | BJ5: 0 | BK5: 0 | BL5: 0 | BM5: 0 | BN5: 0 | BO5: 0 | BP5: 0 | BQ5: 0 | BR5: 0 | BS5: 0 | BT5: 0 | BU5: 0 | BV5: 0 | BW5: 0 | BX5: 0 | BY5: 0 | BZ5: 0 | CA5: 0 | CB5: 0 | CC5: 0 | CD5: 0 | CE5: 0 | CF5: 0 | CG5: 0 | CH5: 0 | CI5: 0 | CJ5: 0 | CK5: 0 | CL5: 0 | CM5: 0 | CN5: 1 | CO5: 1 | CP5: 1 | CQ5: 0 | CR5: 0 | CS5: 0 | CT5: 0
A6: OBS-002 | B6: 31282 | C6: =IF(B6="","",YEAR(B6)) -> 1985 | D6: =IF(B6="","",IF(MONTH(B6)<=2,"Winter",IF(MONTH(B6)<=5,"Spring",IF(MONTH(B6)<=8,"Summer","Fall")))) -> Summer | H6: Hapke and Henderson | I6: 0 | J6: 0 | K6: 0 | L6: 0 | M6: 0 | N6: 0 | O6: 0 | P6: 0 | Q6: 0 | R6: 0 | S6: 0 | T6: 0 | U6: 0 | V6: 0 | W6: 0 | X6: 0 | Y6: 0 | Z6: 0 | AA6: 0 | AB6: 0 | AC6: 0 | AD6: 0 | AE6: 0 | AF6: 0 | AG6: 0 | AH6: 0 | AI6: 0 | AJ6: 0 | AK6: 0 | AL6: 0 | AM6: 0 | AN6: 0 | AO6: 0 | AP6: 0 | AQ6: 0 | AR6: 0 | AS6: 0 | AT6: 0 | AU6: 0 | AV6: 0 | AW6: 0 | AX6: 0 | AY6: 0 | AZ6: 0 | BA6: 0 | BB6: 0 | BC6: 0 | BD6: 0 | BE6: 0 | BF6: 0 | BG6: 0 | BH6: 0 | BI6: 0 | BJ6: 0 | BK6: 0 | BL6: 0 | BM6: 0 | BN6: 0 | BO6: 0 | BP6: 0 | BQ6: 0 | BR6: 0 | BS6: 0 | BT6: 0 | BU6: 0 | BV6: 0 | BW6: 0 | BX6: 0 | BY6: 0 | BZ6: 0 | CA6: 0 | CB6: 0 | CC6: 0 | CD6: 0 | CE6: 0 | CF6: 0 | CG6: 0 | CH6: 0 | CI6: 0 | CJ6: 0 | CK6: 0 | CL6: 0 | CM6: 0 | CN6: 0 | CO6: 0 | CP6: 0 | CQ6: 0 | CR6: 0 | CS6: 0 | CT6: 0
A7: OBS-003 | B7: 31968 | C7: =IF(B7="","",YEAR(B7)) -> 1987 | D7: =IF(B7="","",IF(MONTH(B7)<=2,"Winter",IF(MONTH(B7)<=5,"Spring",IF(MONTH(B7)<=8,"Summer","Fall")))) -> Summer | H7: Hapke and Henderson | I7: 0 | J7: 0 | K7: 0 | L7: 0 | M7: 0 | N7: 0 | O7: 0 | P7: 0 | Q7: 0 | R7: 0 | S7: 0 | T7: 0 | U7: 0 | V7: 0 | W7: 0 | X7: 0 | Y7: 0 | Z7: 0 | AA7: 0 | AB7: 0 | AC7: 0 | AD7: 0 | AE7: 0 | AF7: 0 | AG7: 0 | AH7: 0 | AI7: 0 | AJ7: 0 | AK7: 0 | AL7: 0 | AM7: 0 | AN7: 0 | AO7: 0 | AP7: 0 | AQ7: 0 | AR7: 0 | AS7: 0 | AT7: 0 | AU7: 0 | AV7: 0 | AW7: 0 | AX7: 0 | AY7: 0 | AZ7: 0 | BA7: 0 | BB7: 0 | BC7: 0 | BD7: 0 | BE7: 0 | BF7: 0 | BG7: 0 | BH7: 0 | BI7: 0 | BJ7: 0 | BK7: 0 | BL7: 0 | BM7: 0 | BN7: 0 | BO7: 0 | BP7: 0 | BQ7: 0 | BR7: 0 | BS7: 0 | BT7: 0 | BU7: 0 | BV7: 0 | BW7: 0 | BX7: 0 | BY7: 0 | BZ7: 0 | CA7: 0 | CB7: 0 | CC7: 0 | CD7: 0 | CE7: 0 | CF7: 0 | CG7: 0 | CH7: 0 | CI7: 0 | CJ7: 0 | CK7: 0 | CL7: 0 | CM7: 0 | CN7: 0 | CO7: 0 | CP7: 0 | CQ7: 0 | CR7: 0 | CS7: 0 | CT7: 0
A8: OBS-004 | B8: 32719 | C8: =IF(B8="","",YEAR(B8)) -> 1989 | D8: =IF(B8="","",IF(MONTH(B8)<=2,"Winter",IF(MONTH(B8)<=5,"Spring",IF(MONTH(B8)<=8,"Summer","Fall")))) -> Summer | H8: Hapke and Henderson | I8: 0 | J8: 0 | K8: 0 | L8: 0 | M8: 0 | N8: 0 | O8: 0 | P8: 0 | Q8: 0 | R8: 0 | S8: 0 | T8: 0 | U8: 0 | V8: 0 | W8: 0 | X8: 0 | Y8: 0 | Z8: 0 | AA8: 0 | AB8: 0 | AC8: 0 | AD8: 0 | AE8: 0 | AF8: 0 | AG8: 0 | AH8: 0 | AI8: 0 | AJ8: 0 | AK8: 0 | AL8: 0 | AM8: 0 | AN8: 0 | AO8: 0 | AP8: 0 | AQ8: 0 | AR8: 0 | AS8: 0 | AT8: 0 | AU8: 0 | AV8: 0 | AW8: 0 | AX8: 0 | AY8: 0 | AZ8: 0 | BA8: 0 | BB8: 0 | BC8: 0 | BD8: 0 | BE8: 0 | BF8: 0 | BG8: 1 | BH8: 1 | BI8: 0 | BJ8: 0 | BK8: 0 | BL8: 0 | BM8: 0 | BN8: 0 | BO8: 0 | BP8: 0 | BQ8: 0 | BR8: 0 | BS8: 0 | BT8: 0 | BU8: 0 | BV8: 0 | BW8: 0 | BX8: 0 | BY8: 0 | BZ8: 0 | CA8: 0 | CB8: 0 | CC8: 0 | CD8: 0 | CE8: 0 | CF8: 0 | CG8: 0 | CH8: 0 | CI8: 0 | CJ8: 0 | CK8: 0 | CL8: 0 | CM8: 0 | CN8: 0 | CO8: 0 | CP8: 0 | CQ8: 0 | CR8: 0 | CS8: 0 | CT8: 0
A9: OBS-005 | B9: 33530 | C9: =IF(B9="","",YEAR(B9)) -> 1991 | D9: =IF(B9="","",IF(MONTH(B9)<=2,"Winter",IF(MONTH(B9)<=5,"Spring",IF(MONTH(B9)<=8,"Summer","Fall")))) -> Fall | E9: STM-1991-BOB | F9: BOB | H9: Hapke and Henderson | I9: 0 | J9: 0 | K9: 0 | L9: 0 | M9: 0 | N9: 0 | O9: 0 | P9: 0 | Q9: 0 | R9: 0 | S9: 0 | T9: 0 | U9: 0 | V9: 0 | W9: 0 | X9: 0 | Y9: 0 | Z9: 0 | AA9: 0 | AB9: 0 | AC9: 0 | AD9: 0 | AE9: 0 | AF9: 0 | AG9: 0 | AH9: 0 | AI9: 0 | AJ9: 0 | AK9: 0 | AL9: 0 | AM9: 0 | AN9: 0 | AO9: 0 | AP9: 0 | AQ9: 0 | AR9: 0 | AS9: 0 | AT9: 0 | AU9: 0 | AV9: 0 | AW9: 0 | AX9: 0 | AY9: 0 | AZ9: 0 | BA9: 0 | BB9: 1 | BC9: 1 | BD9: 0 | BE9: 1 | BF9: 1 | BG9: 1 | BH9: 0 | BI9: 1 | BJ9: 0 | BK9: 0 | BL9: 0 | BM9: 0 | BN9: 0 | BO9: 0 | BP9: 0 | BQ9: 0 | BR9: 0 | BS9: 0 | BT9: 0 | BU9: 0 | BV9: 0 | BW9: 0 | BX9: 0 | BY9: 0 | BZ9: 0 | CA9: 0 | CB9: 0 | CC9: 0 | CD9: 0 | CE9: 0 | CF9: 0 | CG9: 0 | CH9: 0 | CI9: 0 | CJ9: 1 | CK9: 1 | CL9: 0 | CM9: 0 | CN9: 0 | CO9: 0 | CP9: 0 | CQ9: 0 | CR9: 0 | CS9: 0 | CT9: 0
A10: OBS-006 | B10: 33879 | C10: =IF(B10="","",YEAR(B10)) -> 1992 | D10: =IF(B10="","",IF(MONTH(B10)<=2,"Winter",IF(MONTH(B10)<=5,"Spring",IF(MONTH(B10)<=8,"Summer","Fall")))) -> Fall | H10: Hapke and Henderson | I10: 0 | J10: 0 | K10: 0 | L10: 0 | M10: 0 | N10: 0 | O10: 0 | P10: 0 | Q10: 1 | R10: 1 | S10: 0 | T10: 0 | U10: 0 | V10: 0 | W10: 0 | X10: 0 | Y10: 0 | Z10: 0 | AA10: 0 | AB10: 0 | AC10: 0 | AD10: 0 | AE10: 0 | AF10: 0 | AG10: 0 | AH10: 0 | AI10: 0 | AJ10: 0 | AK10: 0 | AL10: 0 | AM10: 0 | AN10: 0 | AO10: 0 | AP10: 0 | AQ10: 0 | AR10: 0 | AS10: 0 | AT10: 0 | AU10: 0 | AV10: 0 | AW10: 0 | AX10: 0 | AY10: 0 | AZ10: 0 | BA10: 0 | BB10: 0 | BC10: 0 | BD10: 0 | BE10: 0 | BF10: 0 | BG10: 0 | BH10: 0 | BI10: 0 | BJ10: 0 | BK10: 0 | BL10: 0 | BM10: 0 | BN10: 0 | BO10: 0 | BP10: 0 | BQ10: 0 | BR10: 0 | BS10: 0 | BT10: 0 | BU10: 0 | BV10: 0 | BW10: 0 | BX10: 0 | BY10: 0 | BZ10: 0 | CA10: 0 | CB10: 0 | CC10: 0 | CD10: 0 | CE10: 0 | CF10: 0 | CG10: 0 | CH10: 0 | CI10: 1 | CJ10: 1 | CK10: 1 | CL10: 0 | CM10: 0 | CN10: 1 | CO10: 1 | CP10: 1 | CQ10: 0 | CR10: 0 | CS10: 0 | CT10: 0
A11: OBS-007 | B11: 34214 | C11: =IF(B11="","",YEAR(B11)) -> 1993 | D11: =IF(B11="","",IF(MONTH(B11)<=2,"Winter",IF(MONTH(B11)<=5,"Spring",IF(MONTH(B11)<=8,"Summer","Fall")))) -> Fall | E11: STM-1993-EMI | F11: EMILY | H11: Hapke and Henderson | I11: 0 | J11: 0 | K11: 0 | L11: 0 | M11: 1 | N11: 0 | O11: 0 | P11: 0 | Q11: 0 | R11: 0 | S11: 0 | T11: 0 | U11: 0 | V11: 0 | W11: 0 | X11: 0 | Y11: 0 | Z11: 0 | AA11: 0 | AB11: 0 | AC11: 0 | AD11: 0 | AE11: 0 | AF11: 0 | AG11: 0 | AH11: 0 | AI11: 0 | AJ11: 0 | AK11: 0 | AL11: 0 | AM11: 0 | AN11: 0 | AO11: 0 | AP11: 0 | AQ11: 0 | AR11: 0 | AS11: 0 | AT11: 0 | AU11: 0 | AV11: 0 | AW11: 0 | AX11: 0 | AY11: 0 | AZ11: 0 | BA11: 0 | BB11: 0 | BC11: 0 | BD11: 0 | BE11: 0 | BF11: 0 | BG11: 0 | BH11: 0 | BI11: 0 | BJ11: 0 | BK11: 0 | BL11: 0 | BM11: 0 | BN11: 0 | BO11: 0 | BP11: 0 | BQ11: 0 | BR11: 0 | BS11: 0 | BT11: 0 | BU11: 0 | BV11: 0 | BW11: 0 | BX11: 0 | BY11: 0 | BZ11: 0 | CA11: 0 | CB11: 0 | CC11: 0 | CD11: 0 | CE11: 0 | CF11: 0 | CG11: 0 | CH11: 0 | CI11: 0 | CJ11: 0 | CK11: 0 | CL11: 1 | CM11: 1 | CN11: 0 | CO11: 0 | CP11: 0 | CQ11: 1 | CR11: 1 | CS11: 1 | CT11: 1
A12: OBS-008 | B12: 34990 | C12: =IF(B12="","",YEAR(B12)) -> 1995 | D12: =IF(B12="","",IF(MONTH(B12)<=2,"Winter",IF(MONTH(B12)<=5,"Spring",IF(MONTH(B12)<=8,"Summer","Fall")))) -> Fall | H12: Hapke and Henderson | I12: 0 | J12: 0 | K12: 0 | L12: 0 | M12: 0 | N12: 0 | O12: 0 | P12: 0 | Q12: 0 | R12: 0 | S12: 0 | T12: 0 | U12: 0 | V12: 0 | W12: 0 | X12: 0 | Y12: 0 | Z12: 0 | AA12: 0 | AB12: 0 | AC12: 0 | AD12: 0 | AE12: 0 | AF12: 0 | AG12: 0 | AH12: 0 | AI12: 0 | AJ12: 0 | AK12: 0 | AL12: 0 | AM12: 0 | AN12: 0 | AO12: 0 | AP12: 0 | AQ12: 0 | AR12: 0 | AS12: 0 | AT12: 0 | AU12: 0 | AV12: 0 | AW12: 0 | AX12: 0 | AY12: 0 | AZ12: 0 | BA12: 0 | BB12: 0 | BC12: 0 | BD12: 1 | BE12: 1 | BF12: 1 | BG12: 1 | BH12: 0 | BI12: 1 | BJ12: 1 | BK12: 0 | BL12: 1 | BM12: 1 | BN12: 0 | BO12: 0 | BP12: 0 | BQ12: 0 | BR12: 0 | BS12: 0 | BT12: 0 | BU12: 0 | BV12: 0 | BW12: 0 | BX12: 0 | BY12: 0 | BZ12: 0 | CA12: 0 | CB12: 0 | CC12: 0 | CD12: 0 | CE12: 0 | CF12: 0 | CG12: 0 | CH12: 0 | CI12: 0 | CJ12: 0 | CK12: 0 | CL12: 1 | CM12: 1 | CN12: 0 | CO12: 0 | CP12: 1 | CQ12: 0 | CR12: 0 | CS12: 0 | CT12: 0
A13: OBS-009 | B13: 35352 | C13: =IF(B13="","",YEAR(B13)) -> 1996 | D13: =IF(B13="","",IF(MONTH(B13)<=2,"Winter",IF(MONTH(B13)<=5,"Spring",IF(MONTH(B13)<=8,"Summer","Fall")))) -> Fall | E13: NOR-1996-01 | F13: Jan 1996 Nor'easter | G13: Poor | H13: Hapke and Henderson | I13: 0 | J13: 0 | K13: 1 | L13: 0 | M13: 0 | N13: 0 | O13: 0 | P13: 0 | Q13: 0 | R13: 0 | S13: 0 | T13: 0 | U13: 0 | V13: 0 | W13: 0 | X13: 0 | Y13: 0 | Z13: 0 | AA13: 0 | AB13: 0 | AC13: 0 | AD13: 0 | AE13: 0 | AF13: 0 | AG13: 0 | AH13: 0 | AI13: 0 | AJ13: 0 | AK13: 0 | AL13: 0 | AM13: 0 | AN13: 0 | AO13: 0 | AP13: 0 | AQ13: 0 | AR13: 0 | AS13: 0 | AT13: 0 | AU13: 0 | AV13: 0 | AW13: 0 | AX13: 0 | AY13: 0 | AZ13: 0 | BA13: 0 | BB13: 0 | BC13: 0 | BD13: 0 | BE13: 0 | BG13: 0 | BH13: 0 | BI13: 0 | BJ13: 0 | BK13: 0 | BL13: 0 | BM13: 0 | BN13: 0 | BO13: 0 | BP13: 0 | BQ13: 0 | BR13: 0 | BS13: 0 | BT13: 0 | BU13: 0 | BV13: 0 | BW13: 0 | BX13: 0 | BY13: 0 | BZ13: 0 | CA13: 0 | CB13: 0 | CC13: 0 | CD13: 0 | CE13: 0 | CF13: 0 | CG13: 0 | CH13: 0 | CI13: 0 | CJ13: 0 | CK13: 0 | CL13: 0 | CM13: 0 | CN13: 0 | CO13: 0 | CP13: 0 | CQ13: 0 | CR13: 0 | CS13: 0 | CT13: 0
A14: OBS-010 | B14: 35715 | C14: =IF(B14="","",YEAR(B14)) -> 1997 | D14: =IF(B14="","",IF(MONTH(B14)<=2,"Winter",IF(MONTH(B14)<=5,"Spring",IF(MONTH(B14)<=8,"Summer","Fall")))) -> Fall | H14: Hapke and Henderson | I14: 0 | J14: 0 | K14: 1 | L14: 1 | M14: 0 | N14: 0 | O14: 0 | P14: 0 | Q14: 0 | R14: 0 | S14: 0 | T14: 0 | U14: 0 | V14: 0 | W14: 0 | X14: 0 | Y14: 0 | Z14: 0 | AA14: 0 | AB14: 0 | AC14: 0 | AD14: 0 | AE14: 0 | AF14: 0 | AG14: 0 | AH14: 0 | AI14: 0 | AJ14: 0 | AK14: 0 | AL14: 0 | AM14: 0 | AN14: 0 | AO14: 0 | AP14: 0 | AQ14: 0 | AR14: 0 | AS14: 0 | AT14: 0 | AU14: 0 | AV14: 0 | AW14: 0 | AX14: 0 | AY14: 0 | AZ14: 0 | BA14: 0 | BB14: 0 | BC14: 0 | BD14: 0 | BE14: 0 | BF14: 0 | BG14: 0 | BH14: 0 | BI14: 0 | BJ14: 0 | BK14: 0 | BL14: 0 | BM14: 0 | BN14: 0 | BO14: 0 | BP14: 0 | BQ14: 0 | BR14: 0 | BS14: 0 | BT14: 0 | BU14: 0 | BV14: 0 | BW14: 0 | BX14: 0 | BY14: 0 | BZ14: 0 | CA14: 0 | CB14: 0 | CC14: 0 | CD14: 0 | CE14: 0 | CF14: 0 | CG14: 0 | CH14: 0 | CI14: 0 | CJ14: 0 | CK14: 0 | CL14: 0 | CM14: 0 | CN14: 0 | CO14: 0 | CP14: 0 | CQ14: 0 | CR14: 0 | CS14: 0 | CT14: 0
A15: OBS-011 | B15: 36070 | C15: =IF(B15="","",YEAR(B15)) -> 1998 | D15: =IF(B15="","",IF(MONTH(B15)<=2,"Winter",IF(MONTH(B15)<=5,"Spring",IF(MONTH(B15)<=8,"Summer","Fall")))) -> Fall | E15: STM-1998-BON | F15: BONNIE | H15: Hapke and Henderson | I15: 1 | J15: 1 | K15: 1 | L15: 1 | M15: 1 | N15: 0 | U15: 0 | V15: 0 | W15: 1 | X15: 1 | Y15: 0 | Z15: 0 | AA15: 0 | AB15: 0 | AC15: 0 | AD15: 0 | AE15: 0 | AF15: 0 | AG15: 0 | AH15: 0 | AI15: 0 | AJ15: 0 | AK15: 0 | AL15: 0 | AM15: 0 | AN15: 0 | AO15: 0 | AP15: 0 | AQ15: 0 | AR15: 0 | AS15: 0 | AT15: 0 | AU15: 0 | AV15: 0 | AW15: 0 | AX15: 0 | AY15: 0 | AZ15: 0 | BA15: 0 | BB15: 0 | BC15: 0 | BD15: 0 | BE15: 0 | BF15: 0 | BG15: 0 | BH15: 0 | BI15: 0 | BJ15: 0 | BK15: 0 | BL15: 0 | BM15: 0 | BN15: 0 | BO15: 0 | BP15: 0 | BQ15: 0 | BR15: 0 | BS15: 0 | BT15: 0 | BU15: 0 | BV15: 0 | BW15: 0 | BX15: 0 | BY15: 0 | BZ15: 0 | CA15: 0 | CB15: 0 | CC15: 0 | CD15: 0 | CE15: 0 | CF15: 0 | CG15: 0 | CH15: 0 | CI15: 0 | CJ15: 0 | CK15: 0 | CL15: 0 | CM15: 0 | CN15: 0 | CO15: 0 | CP15: 0 | CQ15: 0 | CR15: 0 | CS15: 0 | CT15: 0
A16: OBS-012 | B16: 38132 | C16: =IF(B16="","",YEAR(B16)) -> 2004 | D16: =IF(B16="","",IF(MONTH(B16)<=2,"Winter",IF(MONTH(B16)<=5,"Spring",IF(MONTH(B16)<=8,"Summer","Fall")))) -> Spring | G16: Medium | H16: Google Earth | I16: 1 | J16: 1 | K16: 1 | L16: 1 | M16: 1 | N16: 1 | O16: 0 | P16: 1 | Q16: 1 | R16: 1 | S16: 1 | T16: 1 | U16: 1 | V16: 0 | W16: 0 | X16: 1 | Y16: 1 | Z16: 1 | AA16: 0 | AB16: 0 | AC16: 0 | AD16: 0 | AE16: 0 | AF16: 0 | AG16: 0 | AH16: 1 | AI16: 1 | AJ16: 0 | AK16: 1 | AL16: 0 | AM16: 0 | AN16: 0 | AO16: 1 | AP16: 1 | AQ16: 1 | AR16: 1 | AS16: 1 | AT16: 0 | AU16: 0 | AV16: 0 | AW16: 0 | AX16: 0 | AY16: 0 | AZ16: 0 | BA16: 0 | BB16: 1 | BC16: 1 | BD16: 1 | BE16: 1 | BF16: 1 | BG16: 1 | BH16: 1 | BI16: 1 | BJ16: 1 | BK16: 1 | BL16: 1 | BM16: 1 | BN16: 1 | BO16: 0 | BP16: 0 | BQ16: 0 | BR16: 0 | BS16: 0 | BT16: 0 | BU16: 0 | BV16: 1 | BW16: 1 | BX16: 0 | BY16: 0 | BZ16: 0 | CA16: 0 | CB16: 0 | CC16: 0 | CD16: 0 | CE16: 0 | CF16: 1 | CG16: 1 | CH16: 1 | CI16: 1 | CJ16: 1 | CK16: 1 | CL16: 1 | CM16: 1 | CN16: 1 | CO16: 1 | CP16: 1 | CQ16: 1 | CR16: 1 | CS16: 0 | CT16: 0
A17: =IF(B17="","",TEXT(ROW()-4,"OBS-000")) | C17: =IF(B17="","",YEAR(B17)) | D17: =IF(B17="","",IF(MONTH(B17)<=2,"Winter",IF(MONTH(B17)<=5,"Spring",IF(MONTH(B17)<=8,"Summer","Fall"))))
A18: =IF(B18="","",TEXT(ROW()-4,"OBS-000")) | C18: =IF(B18="","",YEAR(B18)) | D18: =IF(B18="","",IF(MONTH(B18)<=2,"Winter",IF(MONTH(B18)<=5,"Spring",IF(MONTH(B18)<=8,"Summer","Fall"))))
A19: =IF(B19="","",TEXT(ROW()-4,"OBS-000")) | C19: =IF(B19="","",YEAR(B19)) | D19: =IF(B19="","",IF(MONTH(B19)<=2,"Winter",IF(MONTH(B19)<=5,"Spring",IF(MONTH(B19)<=8,"Summer","Fall"))))
A20: =IF(B20="","",TEXT(ROW()-4,"OBS-000")) | C20: =IF(B20="","",YEAR(B20)) | D20: =IF(B20="","",IF(MONTH(B20)<=2,"Winter",IF(MONTH(B20)<=5,"Spring",IF(MONTH(B20)<=8,"Summer","Fall"))))
A21: =IF(B21="","",TEXT(ROW()-4,"OBS-000")) | C21: =IF(B21="","",YEAR(B21)) | D21: =IF(B21="","",IF(MONTH(B21)<=2,"Winter",IF(MONTH(B21)<=5,"Spring",IF(MONTH(B21)<=8,"Summer","Fall"))))
A22: =IF(B22="","",TEXT(ROW()-4,"OBS-000")) | C22: =IF(B22="","",YEAR(B22)) | D22: =IF(B22="","",IF(MONTH(B22)<=2,"Winter",IF(MONTH(B22)<=5,"Spring",IF(MONTH(B22)<=8,"Summer","Fall"))))
A23: =IF(B23="","",TEXT(ROW()-4,"OBS-000")) | C23: =IF(B23="","",YEAR(B23)) | D23: =IF(B23="","",IF(MONTH(B23)<=2,"Winter",IF(MONTH(B23)<=5,"Spring",IF(MONTH(B23)<=8,"Summer","Fall"))))
A24: =IF(B24="","",TEXT(ROW()-4,"OBS-000")) | C24: =IF(B24="","",YEAR(B24)) | D24: =IF(B24="","",IF(MONTH(B24)<=2,"Winter",IF(MONTH(B24)<=5,"Spring",IF(MONTH(B24)<=8,"Summer","Fall"))))
A25: =IF(B25="","",TEXT(ROW()-4,"OBS-000")) | C25: =IF(B25="","",YEAR(B25)) | D25: =IF(B25="","",IF(MONTH(B25)<=2,"Winter",IF(MONTH(B25)<=5,"Spring",IF(MONTH(B25)<=8,"Summer","Fall"))))
A26: =IF(B26="","",TEXT(ROW()-4,"OBS-000")) | C26: =IF(B26="","",YEAR(B26)) | D26: =IF(B26="","",IF(MONTH(B26)<=2,"Winter",IF(MONTH(B26)<=5,"Spring",IF(MONTH(B26)<=8,"Summer","Fall"))))
A27: =IF(B27="","",TEXT(ROW()-4,"OBS-000")) | C27: =IF(B27="","",YEAR(B27)) | D27: =IF(B27="","",IF(MONTH(B27)<=2,"Winter",IF(MONTH(B27)<=5,"Spring",IF(MONTH(B27)<=8,"Summer","Fall"))))
A28: =IF(B28="","",TEXT(ROW()-4,"OBS-000")) | C28: =IF(B28="","",YEAR(B28)) | D28: =IF(B28="","",IF(MONTH(B28)<=2,"Winter",IF(MONTH(B28)<=5,"Spring",IF(MONTH(B28)<=8,"Summer","Fall"))))
... A500: =IF(B500="","",TEXT(ROW()-4,"OBS-000")) | C500: =IF(B500="","",YEAR(B500)) | D500: =IF(B500="","",IF(MONTH(B500)<=2,"Winter",IF(MONTH(B500)<=5,"Spring",IF(MONTH(B500)<=8,"Summer","Fall"))))

Sheet Storm_Reference
A1: Storm Reference · Use this to identify which imagery dates to search for in Google Earth · This sheet is READ ONLY — do not enter data here
A2: For each storm below, search Google Earth for the first clear image AFTER the date range ends. Enter that imagery date (not the storm date) as a new row in Overwash_Matrix.
A3: Event_ID | B3: Storm_Name | C3: Type | D3: Date_Range | E3: Max_Category | F3: Expected_Impact | G3: Search_GE_After | H3: Notes
A4: STM-1984-DIA | B4: DIANA | C4: Hurricane | D4: Sep 8–16, 1984 | E4: H4 | F4: High | G4: Sep 16, 1984 | H4: Direct OBX impact
A5: STM-1985-GLO | B5: GLORIA | C5: Hurricane | D5: Sep 16–Oct 2, 1985 | E5: H4 | F5: High | G5: Oct 2, 1985 | H5: H4 peak; weakened to ~Cat 1-2 at OBX
A6: STM-1985-KAT | B6: KATE | C6: Hurricane | D6: Nov 15–23, 1985 | E6: H3 | F6: Med | G6: Nov 23, 1985 | H6: Late-season; look for Nov–Dec imagery
A7: STM-1986-CHA | B7: CHARLEY | C7: Hurricane | D7: Aug 13–30, 1986 | E7: H1 | F7: Low | G7: Aug 30, 1986 | H7: Weak; may have limited signature
A8: STM-1988-ALB | B8: ALBERTO | C8: Trop Storm | D8: Aug 5–8, 1988 | E8: TS | F8: Low | G8: Aug 8, 1988 | H8: Weak TS; minor impact likely
A9: NOR-1991-10 | B9: Perfect Storm | C9: Nor'easter | D9: Oct 28–Nov 2, 1991 | E9: Class 5 | F9: High | G9: Nov 2, 1991 | H9: Major OBX impact; ~2 ft surge
A10: STM-1991-BOB | B10: BOB | C10: Hurricane | D10: Aug 16–29, 1991 | E10: H3 | F10: Med | G10: Aug 29, 1991 | H10: H3 but tracked north of OBX
A11: NOR-1992-12 | B11: Dec 1992 Nor'easter | C11: Nor'easter | D11: Dec 10–14, 1992 | E11: Class 4 | F11: High | G11: Dec 14, 1992 | H11: Blizzard of '92; areas hit again after Perfect Storm
A12: NOR-1993-03 | B12: Storm of the Century | C12: Nor'easter | D12: Mar 12–15, 1993 | E12: Class 5 | F12: High | G12: Mar 15, 1993 | H12: Hurricane-force gusts; 200 homes damaged OBX
A13: STM-1993-EMI | B13: EMILY | C13: Hurricane | D13: Aug 22–Sep 6, 1993 | E13: H3 | F13: High | G13: Sep 6, 1993 | H13: Stalled near OBX; prolonged wave exposure
A14: NOR-1996-01 | B14: Jan 1996 Nor'easter | C14: Nor'easter | D14: Jan 6–8, 1996 | E14: Class 4 | F14: High | G14: Jan 8, 1996 | H14: Blizzard of 1996; significant coastal flooding
... A24: NOR-2016-01 | B24: Winter Storm Jonas | C24: Nor'easter | D24: Jan 22–24, 2016 | E24: Class 4-5 | F24: High | G24: Jan 24, 2016 | H24: Record OBX coastal flooding; look Jan–Feb 2016
A25: STM-2016-HER | B25: HERMINE | C25: Hurricane | D25: Aug 28–Sep 8, 2016 | E25: H1 | F25: Med | G25: Sep 8, 2016
A26: STM-2016-MAT | B26: MATTHEW | C26: Hurricane | D26: Sep 28–Oct 10, 2016 | E26: H5 | F26: High | G26: Oct 10, 2016 | H26: H5 at peak; major OBX impacts; look Oct–Nov 2016
A27: NOR-2018-01 | B27: Jan 2018 Bomb Cyclone | C27: Nor'easter | D27: Jan 3–5, 2018 | E27: Class 4 | F27: High | G27: Jan 5, 2018 | H27: Gusts 65–70 mph OBX
A28: STM-2019-DOR | B28: DORIAN | C28: Hurricane | D28: Aug 24–Sep 9, 2019 | E28: H5 | F28: High | G28: Sep 9, 2019 | H28: NC-12 closed ~3 months; expect major overwash; look Oct 2019
A29: STM-2020-TED | B29: TEDDY | C29: Hurricane | D29: Sep 12–23, 2020 | E29: H4 | F29: Med | G29: Sep 23, 2020 | H29: Stayed offshore; NC-12 closed Oregon Inlet–Rodanthe
A30: NOR-2021-11 | B30: Nov 2021 storm | C30: Nor'easter | D30: Nov 2021 | E30: ~Class 3 | F30: Med | G30: Nov 2021 | H30: Breach D84–90 between Rodanthe and Oregon Inlet
A31: NOR-2022-052 | B31: May 2022 Nor'easter | C31: Nor'easter | D31: May 9–11, 2022 | E31: ~Class 3 | F31: Med | G31: May 11, 2022 | H31: Rodanthe house collapses; look D68–83

Sheet Annual_Frequency
A1: Annual Overwash Frequency · Auto-calculated from Overwash_Matrix · Each cell = number of imagery dates in that year where overwash was observed (value = 1) for that domain
C2: Cape Point | I2: Buxton | K2: Inter-village: Buxton–Avon | W2: Avon | AH2: Inter-village: Avon–Tri-Village | BR2: Tri-Village | CH2: Pea Island / N. of Rodanthe
A3: Year | B3: Images Assessed | C3: 1 | D3: 2 | E3: 3 | F3: 4 | G3: 5 | H3: 6 | I3: 7 | J3: 8 | K3: 9 | L3: 10 | M3: 11 | N3: 12 | O3: 13 | P3: 14 | Q3: 15 | R3: 16 | S3: 17 | T3: 18 | U3: 19 | V3: 20 | W3: 21 | X3: 22 | Y3: 23 | Z3: 24 | AA3: 25 | AB3: 26 | AC3: 27 | AD3: 28 | AE3: 29 | AF3: 30 | AG3: 31 | AH3: 32 | AI3: 33 | AJ3: 34 | AK3: 35 | AL3: 36 | AM3: 37 | AN3: 38 | AO3: 39 | AP3: 40 | AQ3: 41 | AR3: 42 | AS3: 43 | AT3: 44 | AU3: 45 | AV3: 46 | AW3: 47 | AX3: 48 | AY3: 49 | AZ3: 50 | BA3: 51 | BB3: 52 | BC3: 53 | BD3: 54 | BE3: 55 | BF3: 56 | BG3: 57 | BH3: 58 | BI3: 59 | BJ3: 60 | BK3: 61 | BL3: 62 | BM3: 63 | BN3: 64 | BO3: 65 | BP3: 66 | BQ3: 67 | BR3: 68 | BS3: 69 | BT3: 70 | BU3: 71 | BV3: 72 | BW3: 73 | BX3: 74 | BY3: 75 | BZ3: 76 | CA3: 77 | CB3: 78 | CC3: 79 | CD3: 80 | CE3: 81 | CF3: 82 | CG3: 83 | CH3: 84 | CI3: 85 | CJ3: 86 | CK3: 87 | CL3: 88 | CM3: 89 | CN3: 90
A4: 1984 | B4: =COUNTIF(Overwash_Matrix!$C:$C,1984) -> 1 | C4: =IF(COUNTIF(Overwash_Matrix!$C:$C,1984)=0,"",COUNTIFS(Overwash_Matrix!$C:$C,1984,Overwash_Matrix!I:I,1)) -> 0 | D4: =IF(COUNTIF(Overwash_Matrix!$C:$C,1984)=0,"",COUNTIFS(Overwash_Matrix!$C:$C,1984,Overwash_Matrix!J:J,1)) -> 0 | E4: =IF(COUNTIF(Overwash_Matrix!$C:$C,1984)=0,"",COUNTIFS(Overwash_Matrix!$C:$C,1984,Overwash_Matrix!K:K,1)) -> 0 | F4: =IF(COUNTIF(Overwash_Matrix!$C:$C,1984)=0,"",COUNTIFS(Overwash_Matrix!$C:$C,1984,Overwash_Matrix!L:L,1)) -> 0 | G4: =IF(COUNTIF(Overwash_Matrix!$C:$C,1984)=0,"",COUNTIFS(Overwash_Matrix!$C:$C,1984,Overwash_Matrix!M:M,1)) -> 0 | H4: =IF(COUNTIF(Overwash_Matrix!$C:$C,1984)=0,"",COUNTIFS(Overwash_Matrix!$C:$C,1984,Overwash_Matrix!N:N,1)) -> 0 | I4: =IF(COUNTIF(Overwash_Matrix!$C:$C,1984)=0,"",COUNTIFS(Overwash_Matrix!$C:$C,1984,Overwash_Matrix!O:O,1)) -> 0 | J4: =IF(COUNTIF(Overwash_Matrix!$C:$C,1984)=0,"",COUNTIFS(Overwash_Matrix!$C:$C,1984,Overwash_Matrix!P:P,1)) -> 0 | K4: =IF(COUNTIF(Overwash_Matrix!$C:$C,1984)=0,"",COUNTIFS(Overwash_Matrix!$C:$C,1984,Overwash_Matrix!Q:Q,1)) -> 0 | L4: =IF(COUNTIF(Overwash_Matrix!$C:$C,1984)=0,"",COUNTIFS(Overwash_Matrix!$C:$C,1984,Overwash_Matrix!R:R,1)) -> 0 | M4: =IF(COUNTIF(Overwash_Matrix!$C:$C,1984)=0,"",COUNTIFS(Overwash_Matrix!$C:$C,1984,Overwash_Matrix!S:S,1)) -> 0 | N4: =IF(COUNTIF(Overwash_Matrix!$C:$C,1984)=0,"",COUNTIFS(Overwash_Matrix!$C:$C,1984,Overwash_Matrix!T:T,1)) -> 0 | O4: =IF(COUNTIF(Overwash_Matrix!$C:$C,1984)=0,"",COUNTIFS(Overwash_Matrix!$C:$C,1984,Overwash_Matrix!U:U,1)) -> 0 | P4: =IF(COUNTIF(Overwash_Matrix!$C:$C,1984)=0,"",COUNTIFS(Overwash_Matrix!$C:$C,1984,Overwash_Matrix!V:V,1)) -> 0 | Q4: =IF(COUNTIF(Overwash_Matrix!$C:$C,1984)=0,"",COUNTIFS(Overwash_Matrix!$C:$C,1984,Overwash_Matrix!W:W,1)) -> 0 | R4: =IF(COUNTIF(Overwash_Matrix!$C:$C,1984)=0,"",COUNTIFS(Overwash_Matrix!$C:$C,1984,Overwash_Matrix!X:X,1)) -> 0 | S4: =IF(COUNTIF(Overwash_Matrix!$C:$C,1984)=0,"",COUNTIFS(Overwash_Matrix!$C:$C,1984,Overwash_Matrix!Y:Y,1)) -> 0 | T4: =IF(COUNTIF(Overwash_Matrix!$C:$C,1984)=0,"",COUNTIFS(Overwash_Matrix!$C:$C,1984,Overwash_Matrix!Z:Z,1)) -> 0 | U4: =IF(COUNTIF(Overwash_Matrix!$C:$C,1984)=0,"",COUNTIFS(Overwash_Matrix!$C:$C,1984,Overwash_Matrix!AA:AA,1)) -> 0 | V4: =IF(COUNTIF(Overwash_Matrix!$C:$C,1984)=0,"",COUNTIFS(Overwash_Matrix!$C:$C,1984,Overwash_Matrix!AB:AB,1)) -> 0 | W4: =IF(COUNTIF(Overwash_Matrix!$C:$C,1984)=0,"",COUNTIFS(Overwash_Matrix!$C:$C,1984,Overwash_Matrix!AC:AC,1)) -> 0 | X4: =IF(COUNTIF(Overwash_Matrix!$C:$C,1984)=0,"",COUNTIFS(Overwash_Matrix!$C:$C,1984,Overwash_Matrix!AD:AD,1)) -> 0 | Y4: =IF(COUNTIF(Overwash_Matrix!$C:$C,1984)=0,"",COUNTIFS(Overwash_Matrix!$C:$C,1984,Overwash_Matrix!AE:AE,1)) -> 0 | Z4: =IF(COUNTIF(Overwash_Matrix!$C:$C,1984)=0,"",COUNTIFS(Overwash_Matrix!$C:$C,1984,Overwash_Matrix!AF:AF,1)) -> 0 | AA4: =IF(COUNTIF(Overwash_Matrix!$C:$C,1984)=0,"",COUNTIFS(Overwash_Matrix!$C:$C,1984,Overwash_Matrix!AG:AG,1)) -> 0 | AB4: =IF(COUNTIF(Overwash_Matrix!$C:$C,1984)=0,"",COUNTIFS(Overwash_Matrix!$C:$C,1984,Overwash_Matrix!AH:AH,1)) -> 0 | AC4: =IF(COUNTIF(Overwash_Matrix!$C:$C,1984)=0,"",COUNTIFS(Overwash_Matrix!$C:$C,1984,Overwash_Matrix!AI:AI,1)) -> 0 | AD4: =IF(COUNTIF(Overwash_Matrix!$C:$C,1984)=0,"",COUNTIFS(Overwash_Matrix!$C:$C,1984,Overwash_Matrix!AJ:AJ,1)) -> 0 | AE4: =IF(COUNTIF(Overwash_Matrix!$C:$C,1984)=0,"",COUNTIFS(Overwash_Matrix!$C:$C,1984,Overwash_Matrix!AK:AK,1)) -> 0 | AF4: =IF(COUNTIF(Overwash_Matrix!$C:$C,1984)=0,"",COUNTIFS(Overwash_Matrix!$C:$C,1984,Overwash_Matrix!AL:AL,1)) -> 0 | AG4: =IF(COUNTIF(Overwash_Matrix!$C:$C,1984)=0,"",COUNTIFS(Overwash_Matrix!$C:$C,1984,Overwash_Matrix!AM:AM,1)) -> 0 | AH4: =IF(COUNTIF(Overwash_Matrix!$C:$C,1984)=0,"",COUNTIFS(Overwash_Matrix!$C:$C,1984,Overwash_Matrix!AN:AN,1)) -> 0 | AI4: =IF(COUNTIF(Overwash_Matrix!$C:$C,1984)=0,"",COUNTIFS(Overwash_Matrix!$C:$C,1984,Overwash_Matrix!AO:AO,1)) -> 0 | AJ4: =IF(COUNTIF(Overwash_Matrix!$C:$C,1984)=0,"",COUNTIFS(Overwash_Matrix!$C:$C,1984,Overwash_Matrix!AP:AP,1)) -> 0 | AK4: =IF(COUNTIF(Overwash_Matrix!$C:$C,1984)=0,"",COUNTIFS(Overwash_Matrix!$C:$C,1984,Overwash_Matrix!AQ:AQ,1)) -> 0 | AL4: =IF(COUNTIF(Overwash_Matrix!$C:$C,1984)=0,"",COUNTIFS(Overwash_Matrix!$C:$C,1984,Overwash_Matrix!AR:AR,1)) -> 0 | AM4: =IF(COUNTIF(Overwash_Matrix!$C:$C,1984)=0,"",COUNTIFS(Overwash_Matrix!$C:$C,1984,Overwash_Matrix!AS:AS,1)) -> 0 | AN4: =IF(COUNTIF(Overwash_Matrix!$C:$C,1984)=0,"",COUNTIFS(Overwash_Matrix!$C:$C,1984,Overwash_Matrix!AT:AT,1)) -> 0 | AO4: =IF(COUNTIF(Overwash_Matrix!$C:$C,1984)=0,"",COUNTIFS(Overwash_Matrix!$C:$C,1984,Overwash_Matrix!AU:AU,1)) -> 0 | AP4: =IF(COUNTIF(Overwash_Matrix!$C:$C,1984)=0,"",COUNTIFS(Overwash_Matrix!$C:$C,1984,Overwash_Matrix!AV:AV,1)) -> 0 | AQ4: =IF(COUNTIF(Overwash_Matrix!$C:$C,1984)=0,"",COUNTIFS(Overwash_Matrix!$C:$C,1984,Overwash_Matrix!AW:AW,1)) -> 0 | AR4: =IF(COUNTIF(Overwash_Matrix!$C:$C,1984)=0,"",COUNTIFS(Overwash_Matrix!$C:$C,1984,Overwash_Matrix!AX:AX,1)) -> 0 | AS4: =IF(COUNTIF(Overwash_Matrix!$C:$C,1984)=0,"",COUNTIFS(Overwash_Matrix!$C:$C,1984,Overwash_Matrix!AY:AY,1)) -> 0 | AT4: =IF(COUNTIF(Overwash_Matrix!$C:$C,1984)=0,"",COUNTIFS(Overwash_Matrix!$C:$C,1984,Overwash_Matrix!AZ:AZ,1)) -> 0 | AU4: =IF(COUNTIF(Overwash_Matrix!$C:$C,1984)=0,"",COUNTIFS(Overwash_Matrix!$C:$C,1984,Overwash_Matrix!BA:BA,1)) -> 0 | AV4: =IF(COUNTIF(Overwash_Matrix!$C:$C,1984)=0,"",COUNTIFS(Overwash_Matrix!$C:$C,1984,Overwash_Matrix!BB:BB,1)) -> 0 | AW4: =IF(COUNTIF(Overwash_Matrix!$C:$C,1984)=0,"",COUNTIFS(Overwash_Matrix!$C:$C,1984,Overwash_Matrix!BC:BC,1)) -> 0 | AX4: =IF(COUNTIF(Overwash_Matrix!$C:$C,1984)=0,"",COUNTIFS(Overwash_Matrix!$C:$C,1984,Overwash_Matrix!BD:BD,1)) -> 0 | AY4: =IF(COUNTIF(Overwash_Matrix!$C:$C,1984)=0,"",COUNTIFS(Overwash_Matrix!$C:$C,1984,Overwash_Matrix!BE:BE,1)) -> 0 | AZ4: =IF(COUNTIF(Overwash_Matrix!$C:$C,1984)=0,"",COUNTIFS(Overwash_Matrix!$C:$C,1984,Overwash_Matrix!BF:BF,1)) -> 0 | BA4: =IF(COUNTIF(Overwash_Matrix!$C:$C,1984)=0,"",COUNTIFS(Overwash_Matrix!$C:$C,1984,Overwash_Matrix!BG:BG,1)) -> 0 | BB4: =IF(COUNTIF(Overwash_Matrix!$C:$C,1984)=0,"",COUNTIFS(Overwash_Matrix!$C:$C,1984,Overwash_Matrix!BH:BH,1)) -> 0 | BC4: =IF(COUNTIF(Overwash_Matrix!$C:$C,1984)=0,"",COUNTIFS(Overwash_Matrix!$C:$C,1984,Overwash_Matrix!BI:BI,1)) -> 0 | BD4: =IF(COUNTIF(Overwash_Matrix!$C:$C,1984)=0,"",COUNTIFS(Overwash_Matrix!$C:$C,1984,Overwash_Matrix!BJ:BJ,1)) -> 0 | BE4: =IF(COUNTIF(Overwash_Matrix!$C:$C,1984)=0,"",COUNTIFS(Overwash_Matrix!$C:$C,1984,Overwash_Matrix!BK:BK,1)) -> 0 | BF4: =IF(COUNTIF(Overwash_Matrix!$C:$C,1984)=0,"",COUNTIFS(Overwash_Matrix!$C:$C,1984,Overwash_Matrix!BL:BL,1)) -> 0 | BG4: =IF(COUNTIF(Overwash_Matrix!$C:$C,1984)=0,"",COUNTIFS(Overwash_Matrix!$C:$C,1984,Overwash_Matrix!BM:BM,1)) -> 0 | BH4: =IF(COUNTIF(Overwash_Matrix!$C:$C,1984)=0,"",COUNTIFS(Overwash_Matrix!$C:$C,1984,Overwash_Matrix!BN:BN,1)) -> 0 | BI4: =IF(COUNTIF(Overwash_Matrix!$C:$C,1984)=0,"",COUNTIFS(Overwash_Matrix!$C:$C,1984,Overwash_Matrix!BO:BO,1)) -> 0 | BJ4: =IF(COUNTIF(Overwash_Matrix!$C:$C,1984)=0,"",COUNTIFS(Overwash_Matrix!$C:$C,1984,Overwash_Matrix!BP:BP,1)) -> 0 | BK4: =IF(COUNTIF(Overwash_Matrix!$C:$C,1984)=0,"",COUNTIFS(Overwash_Matrix!$C:$C,1984,Overwash_Matrix!BQ:BQ,1)) -> 0 | BL4: =IF(COUNTIF(Overwash_Matrix!$C:$C,1984)=0,"",COUNTIFS(Overwash_Matrix!$C:$C,1984,Overwash_Matrix!BR:BR,1)) -> 0 | BM4: =IF(COUNTIF(Overwash_Matrix!$C:$C,1984)=0,"",COUNTIFS(Overwash_Matrix!$C:$C,1984,Overwash_Matrix!BS:BS,1)) -> 0 | BN4: =IF(COUNTIF(Overwash_Matrix!$C:$C,1984)=0,"",COUNTIFS(Overwash_Matrix!$C:$C,1984,Overwash_Matrix!BT:BT,1)) -> 0 | BO4: =IF(COUNTIF(Overwash_Matrix!$C:$C,1984)=0,"",COUNTIFS(Overwash_Matrix!$C:$C,1984,Overwash_Matrix!BU:BU,1)) -> 0 | BP4: =IF(COUNTIF(Overwash_Matrix!$C:$C,1984)=0,"",COUNTIFS(Overwash_Matrix!$C:$C,1984,Overwash_Matrix!BV:BV,1)) -> 0 | BQ4: =IF(COUNTIF(Overwash_Matrix!$C:$C,1984)=0,"",COUNTIFS(Overwash_Matrix!$C:$C,1984,Overwash_Matrix!BW:BW,1)) -> 0 | BR4: =IF(COUNTIF(Overwash_Matrix!$C:$C,1984)=0,"",COUNTIFS(Overwash_Matrix!$C:$C,1984,Overwash_Matrix!BX:BX,1)) -> 0 | BS4: =IF(COUNTIF(Overwash_Matrix!$C:$C,1984)=0,"",COUNTIFS(Overwash_Matrix!$C:$C,1984,Overwash_Matrix!BY:BY,1)) -> 0 | BT4: =IF(COUNTIF(Overwash_Matrix!$C:$C,1984)=0,"",COUNTIFS(Overwash_Matrix!$C:$C,1984,Overwash_Matrix!BZ:BZ,1)) -> 0 | BU4: =IF(COUNTIF(Overwash_Matrix!$C:$C,1984)=0,"",COUNTIFS(Overwash_Matrix!$C:$C,1984,Overwash_Matrix!CA:CA,1)) -> 0 | BV4: =IF(COUNTIF(Overwash_Matrix!$C:$C,1984)=0,"",COUNTIFS(Overwash_Matrix!$C:$C,1984,Overwash_Matrix!CB:CB,1)) -> 0 | BW4: =IF(COUNTIF(Overwash_Matrix!$C:$C,1984)=0,"",COUNTIFS(Overwash_Matrix!$C:$C,1984,Overwash_Matrix!CC:CC,1)) -> 0 | BX4: =IF(COUNTIF(Overwash_Matrix!$C:$C,1984)=0,"",COUNTIFS(Overwash_Matrix!$C:$C,1984,Overwash_Matrix!CD:CD,1)) -> 0 | BY4: =IF(COUNTIF(Overwash_Matrix!$C:$C,1984)=0,"",COUNTIFS(Overwash_Matrix!$C:$C,1984,Overwash_Matrix!CE:CE,1)) -> 0 | BZ4: =IF(COUNTIF(Overwash_Matrix!$C:$C,1984)=0,"",COUNTIFS(Overwash_Matrix!$C:$C,1984,Overwash_Matrix!CF:CF,1)) -> 0 | CA4: =IF(COUNTIF(Overwash_Matrix!$C:$C,1984)=0,"",COUNTIFS(Overwash_Matrix!$C:$C,1984,Overwash_Matrix!CG:CG,1)) -> 0 | CB4: =IF(COUNTIF(Overwash_Matrix!$C:$C,1984)=0,"",COUNTIFS(Overwash_Matrix!$C:$C,1984,Overwash_Matrix!CH:CH,1)) -> 0 | CC4: =IF(COUNTIF(Overwash_Matrix!$C:$C,1984)=0,"",COUNTIFS(Overwash_Matrix!$C:$C,1984,Overwash_Matrix!CI:CI,1)) -> 0 | CD4: =IF(COUNTIF(Overwash_Matrix!$C:$C,1984)=0,"",COUNTIFS(Overwash_Matrix!$C:$C,1984,Overwash_Matrix!CJ:CJ,1)) -> 0 | CE4: =IF(COUNTIF(Overwash_Matrix!$C:$C,1984)=0,"",COUNTIFS(Overwash_Matrix!$C:$C,1984,Overwash_Matrix!CK:CK,1)) -> 0 | CF4: =IF(COUNTIF(Overwash_Matrix!$C:$C,1984)=0,"",COUNTIFS(Overwash_Matrix!$C:$C,1984,Overwash_Matrix!CL:CL,1)) -> 0 | CG4: =IF(COUNTIF(Overwash_Matrix!$C:$C,1984)=0,"",COUNTIFS(Overwash_Matrix!$C:$C,1984,Overwash_Matrix!CM:CM,1)) -> 0 | CH4: =IF(COUNTIF(Overwash_Matrix!$C:$C,1984)=0,"",COUNTIFS(Overwash_Matrix!$C:$C,1984,Overwash_Matrix!CN:CN,1)) -> 1 | CI4: =IF(COUNTIF(Overwash_Matrix!$C:$C,1984)=0,"",COUNTIFS(Overwash_Matrix!$C:$C,1984,Overwash_Matrix!CO:CO,1)) -> 1 | CJ4: =IF(COUNTIF(Overwash_Matrix!$C:$C,1984)=0,"",COUNTIFS(Overwash_Matrix!$C:$C,1984,Overwash_Matrix!CP:CP,1)) -> 1 | CK4: =IF(COUNTIF(Overwash_Matrix!$C:$C,1984)=0,"",COUNTIFS(Overwash_Matrix!$C:$C,1984,Overwash_Matrix!CQ:CQ,1)) -> 0 | CL4: =IF(COUNTIF(Overwash_Matrix!$C:$C,1984)=0,"",COUNTIFS(Overwash_Matrix!$C:$C,1984,Overwash_Matrix!CR:CR,1)) -> 0 | CM4: =IF(COUNTIF(Overwash_Matrix!$C:$C,1984)=0,"",COUNTIFS(Overwash_Matrix!$C:$C,1984,Overwash_Matrix!CS:CS,1)) -> 0 | CN4: =IF(COUNTIF(Overwash_Matrix!$C:$C,1984)=0,"",COUNTIFS(Overwash_Matrix!$C:$C,1984,Overwash_Matrix!CT:CT,1)) -> 0
A5: 1985 | B5: =COUNTIF(Overwash_Matrix!$C:$C,1985) -> 1 | C5: =IF(COUNTIF(Overwash_Matrix!$C:$C,1985)=0,"",COUNTIFS(Overwash_Matrix!$C:$C,1985,Overwash_Matrix!I:I,1)) -> 0 | D5: =IF(COUNTIF(Overwash_Matrix!$C:$C,1985)=0,"",COUNTIFS(Overwash_Matrix!$C:$C,1985,Overwash_Matrix!J:J,1)) -> 0 | E5: =IF(COUNTIF(Overwash_Matrix!$C:$C,1985)=0,"",COUNTIFS(Overwash_Matrix!$C:$C,1985,Overwash_Matrix!K:K,1)) -> 0 | F5: =IF(COUNTIF(Overwash_Matrix!$C:$C,1985)=0,"",COUNTIFS(Overwash_Matrix!$C:$C,1985,Overwash_Matrix!L:L,1)) -> 0 | G5: =IF(COUNTIF(Overwash_Matrix!$C:$C,1985)=0,"",COUNTIFS(Overwash_Matrix!$C:$C,1985,Overwash_Matrix!M:M,1)) -> 0 | H5: =IF(COUNTIF(Overwash_Matrix!$C:$C,1985)=0,"",COUNTIFS(Overwash_Matrix!$C:$C,1985,Overwash_Matrix!N:N,1)) -> 0 | I5: =IF(COUNTIF(Overwash_Matrix!$C:$C,1985)=0,"",COUNTIFS(Overwash_Matrix!$C:$C,1985,Overwash_Matrix!O:O,1)) -> 0 | J5: =IF(COUNTIF(Overwash_Matrix!$C:$C,1985)=0,"",COUNTIFS(Overwash_Matrix!$C:$C,1985,Overwash_Matrix!P:P,1)) -> 0 | K5: =IF(COUNTIF(Overwash_Matrix!$C:$C,1985)=0,"",COUNTIFS(Overwash_Matrix!$C:$C,1985,Overwash_Matrix!Q:Q,1)) -> 0 | L5: =IF(COUNTIF(Overwash_Matrix!$C:$C,1985)=0,"",COUNTIFS(Overwash_Matrix!$C:$C,1985,Overwash_Matrix!R:R,1)) -> 0 | M5: =IF(COUNTIF(Overwash_Matrix!$C:$C,1985)=0,"",COUNTIFS(Overwash_Matrix!$C:$C,1985,Overwash_Matrix!S:S,1)) -> 0 | N5: =IF(COUNTIF(Overwash_Matrix!$C:$C,1985)=0,"",COUNTIFS(Overwash_Matrix!$C:$C,1985,Overwash_Matrix!T:T,1)) -> 0 | O5: =IF(COUNTIF(Overwash_Matrix!$C:$C,1985)=0,"",COUNTIFS(Overwash_Matrix!$C:$C,1985,Overwash_Matrix!U:U,1)) -> 0 | P5: =IF(COUNTIF(Overwash_Matrix!$C:$C,1985)=0,"",COUNTIFS(Overwash_Matrix!$C:$C,1985,Overwash_Matrix!V:V,1)) -> 0 | Q5: =IF(COUNTIF(Overwash_Matrix!$C:$C,1985)=0,"",COUNTIFS(Overwash_Matrix!$C:$C,1985,Overwash_Matrix!W:W,1)) -> 0 | R5: =IF(COUNTIF(Overwash_Matrix!$C:$C,1985)=0,"",COUNTIFS(Overwash_Matrix!$C:$C,1985,Overwash_Matrix!X:X,1)) -> 0 | S5: =IF(COUNTIF(Overwash_Matrix!$C:$C,1985)=0,"",COUNTIFS(Overwash_Matrix!$C:$C,1985,Overwash_Matrix!Y:Y,1)) -> 0 | T5: =IF(COUNTIF(Overwash_Matrix!$C:$C,1985)=0,"",COUNTIFS(Overwash_Matrix!$C:$C,1985,Overwash_Matrix!Z:Z,1)) -> 0 | U5: =IF(COUNTIF(Overwash_Matrix!$C:$C,1985)=0,"",COUNTIFS(Overwash_Matrix!$C:$C,1985,Overwash_Matrix!AA:AA,1)) -> 0 | V5: =IF(COUNTIF(Overwash_Matrix!$C:$C,1985)=0,"",COUNTIFS(Overwash_Matrix!$C:$C,1985,Overwash_Matrix!AB:AB,1)) -> 0 | W5: =IF(COUNTIF(Overwash_Matrix!$C:$C,1985)=0,"",COUNTIFS(Overwash_Matrix!$C:$C,1985,Overwash_Matrix!AC:AC,1)) -> 0 | X5: =IF(COUNTIF(Overwash_Matrix!$C:$C,1985)=0,"",COUNTIFS(Overwash_Matrix!$C:$C,1985,Overwash_Matrix!AD:AD,1)) -> 0 | Y5: =IF(COUNTIF(Overwash_Matrix!$C:$C,1985)=0,"",COUNTIFS(Overwash_Matrix!$C:$C,1985,Overwash_Matrix!AE:AE,1)) -> 0 | Z5: =IF(COUNTIF(Overwash_Matrix!$C:$C,1985)=0,"",COUNTIFS(Overwash_Matrix!$C:$C,1985,Overwash_Matrix!AF:AF,1)) -> 0 | AA5: =IF(COUNTIF(Overwash_Matrix!$C:$C,1985)=0,"",COUNTIFS(Overwash_Matrix!$C:$C,1985,Overwash_Matrix!AG:AG,1)) -> 0 | AB5: =IF(COUNTIF(Overwash_Matrix!$C:$C,1985)=0,"",COUNTIFS(Overwash_Matrix!$C:$C,1985,Overwash_Matrix!AH:AH,1)) -> 0 | AC5: =IF(COUNTIF(Overwash_Matrix!$C:$C,1985)=0,"",COUNTIFS(Overwash_Matrix!$C:$C,1985,Overwash_Matrix!AI:AI,1)) -> 0 | AD5: =IF(COUNTIF(Overwash_Matrix!$C:$C,1985)=0,"",COUNTIFS(Overwash_Matrix!$C:$C,1985,Overwash_Matrix!AJ:AJ,1)) -> 0 | AE5: =IF(COUNTIF(Overwash_Matrix!$C:$C,1985)=0,"",COUNTIFS(Overwash_Matrix!$C:$C,1985,Overwash_Matrix!AK:AK,1)) -> 0 | AF5: =IF(COUNTIF(Overwash_Matrix!$C:$C,1985)=0,"",COUNTIFS(Overwash_Matrix!$C:$C,1985,Overwash_Matrix!AL:AL,1)) -> 0 | AG5: =IF(COUNTIF(Overwash_Matrix!$C:$C,1985)=0,"",COUNTIFS(Overwash_Matrix!$C:$C,1985,Overwash_Matrix!AM:AM,1)) -> 0 | AH5: =IF(COUNTIF(Overwash_Matrix!$C:$C,1985)=0,"",COUNTIFS(Overwash_Matrix!$C:$C,1985,Overwash_Matrix!AN:AN,1)) -> 0 | AI5: =IF(COUNTIF(Overwash_Matrix!$C:$C,1985)=0,"",COUNTIFS(Overwash_Matrix!$C:$C,1985,Overwash_Matrix!AO:AO,1)) -> 0 | AJ5: =IF(COUNTIF(Overwash_Matrix!$C:$C,1985)=0,"",COUNTIFS(Overwash_Matrix!$C:$C,1985,Overwash_Matrix!AP:AP,1)) -> 0 | AK5: =IF(COUNTIF(Overwash_Matrix!$C:$C,1985)=0,"",COUNTIFS(Overwash_Matrix!$C:$C,1985,Overwash_Matrix!AQ:AQ,1)) -> 0 | AL5: =IF(COUNTIF(Overwash_Matrix!$C:$C,1985)=0,"",COUNTIFS(Overwash_Matrix!$C:$C,1985,Overwash_Matrix!AR:AR,1)) -> 0 | AM5: =IF(COUNTIF(Overwash_Matrix!$C:$C,1985)=0,"",COUNTIFS(Overwash_Matrix!$C:$C,1985,Overwash_Matrix!AS:AS,1)) -> 0 | AN5: =IF(COUNTIF(Overwash_Matrix!$C:$C,1985)=0,"",COUNTIFS(Overwash_Matrix!$C:$C,1985,Overwash_Matrix!AT:AT,1)) -> 0 | AO5: =IF(COUNTIF(Overwash_Matrix!$C:$C,1985)=0,"",COUNTIFS(Overwash_Matrix!$C:$C,1985,Overwash_Matrix!AU:AU,1)) -> 0 | AP5: =IF(COUNTIF(Overwash_Matrix!$C:$C,1985)=0,"",COUNTIFS(Overwash_Matrix!$C:$C,1985,Overwash_Matrix!AV:AV,1)) -> 0 | AQ5: =IF(COUNTIF(Overwash_Matrix!$C:$C,1985)=0,"",COUNTIFS(Overwash_Matrix!$C:$C,1985,Overwash_Matrix!AW:AW,1)) -> 0 | AR5: =IF(COUNTIF(Overwash_Matrix!$C:$C,1985)=0,"",COUNTIFS(Overwash_Matrix!$C:$C,1985,Overwash_Matrix!AX:AX,1)) -> 0 | AS5: =IF(COUNTIF(Overwash_Matrix!$C:$C,1985)=0,"",COUNTIFS(Overwash_Matrix!$C:$C,1985,Overwash_Matrix!AY:AY,1)) -> 0 | AT5: =IF(COUNTIF(Overwash_Matrix!$C:$C,1985)=0,"",COUNTIFS(Overwash_Matrix!$C:$C,1985,Overwash_Matrix!AZ:AZ,1)) -> 0 | AU5: =IF(COUNTIF(Overwash_Matrix!$C:$C,1985)=0,"",COUNTIFS(Overwash_Matrix!$C:$C,1985,Overwash_Matrix!BA:BA,1)) -> 0 | AV5: =IF(COUNTIF(Overwash_Matrix!$C:$C,1985)=0,"",COUNTIFS(Overwash_Matrix!$C:$C,1985,Overwash_Matrix!BB:BB,1)) -> 0 | AW5: =IF(COUNTIF(Overwash_Matrix!$C:$C,1985)=0,"",COUNTIFS(Overwash_Matrix!$C:$C,1985,Overwash_Matrix!BC:BC,1)) -> 0 | AX5: =IF(COUNTIF(Overwash_Matrix!$C:$C,1985)=0,"",COUNTIFS(Overwash_Matrix!$C:$C,1985,Overwash_Matrix!BD:BD,1)) -> 0 | AY5: =IF(COUNTIF(Overwash_Matrix!$C:$C,1985)=0,"",COUNTIFS(Overwash_Matrix!$C:$C,1985,Overwash_Matrix!BE:BE,1)) -> 0 | AZ5: =IF(COUNTIF(Overwash_Matrix!$C:$C,1985)=0,"",COUNTIFS(Overwash_Matrix!$C:$C,1985,Overwash_Matrix!BF:BF,1)) -> 0 | BA5: =IF(COUNTIF(Overwash_Matrix!$C:$C,1985)=0,"",COUNTIFS(Overwash_Matrix!$C:$C,1985,Overwash_Matrix!BG:BG,1)) -> 0 | BB5: =IF(COUNTIF(Overwash_Matrix!$C:$C,1985)=0,"",COUNTIFS(Overwash_Matrix!$C:$C,1985,Overwash_Matrix!BH:BH,1)) -> 0 | BC5: =IF(COUNTIF(Overwash_Matrix!$C:$C,1985)=0,"",COUNTIFS(Overwash_Matrix!$C:$C,1985,Overwash_Matrix!BI:BI,1)) -> 0 | BD5: =IF(COUNTIF(Overwash_Matrix!$C:$C,1985)=0,"",COUNTIFS(Overwash_Matrix!$C:$C,1985,Overwash_Matrix!BJ:BJ,1)) -> 0 | BE5: =IF(COUNTIF(Overwash_Matrix!$C:$C,1985)=0,"",COUNTIFS(Overwash_Matrix!$C:$C,1985,Overwash_Matrix!BK:BK,1)) -> 0 | BF5: =IF(COUNTIF(Overwash_Matrix!$C:$C,1985)=0,"",COUNTIFS(Overwash_Matrix!$C:$C,1985,Overwash_Matrix!BL:BL,1)) -> 0 | BG5: =IF(COUNTIF(Overwash_Matrix!$C:$C,1985)=0,"",COUNTIFS(Overwash_Matrix!$C:$C,1985,Overwash_Matrix!BM:BM,1)) -> 0 | BH5: =IF(COUNTIF(Overwash_Matrix!$C:$C,1985)=0,"",COUNTIFS(Overwash_Matrix!$C:$C,1985,Overwash_Matrix!BN:BN,1)) -> 0 | BI5: =IF(COUNTIF(Overwash_Matrix!$C:$C,1985)=0,"",COUNTIFS(Overwash_Matrix!$C:$C,1985,Overwash_Matrix!BO:BO,1)) -> 0 | BJ5: =IF(COUNTIF(Overwash_Matrix!$C:$C,1985)=0,"",COUNTIFS(Overwash_Matrix!$C:$C,1985,Overwash_Matrix!BP:BP,1)) -> 0 | BK5: =IF(COUNTIF(Overwash_Matrix!$C:$C,1985)=0,"",COUNTIFS(Overwash_Matrix!$C:$C,1985,Overwash_Matrix!BQ:BQ,1)) -> 0 | BL5: =IF(COUNTIF(Overwash_Matrix!$C:$C,1985)=0,"",COUNTIFS(Overwash_Matrix!$C:$C,1985,Overwash_Matrix!BR:BR,1)) -> 0 | BM5: =IF(COUNTIF(Overwash_Matrix!$C:$C,1985)=0,"",COUNTIFS(Overwash_Matrix!$C:$C,1985,Overwash_Matrix!BS:BS,1)) -> 0 | BN5: =IF(COUNTIF(Overwash_Matrix!$C:$C,1985)=0,"",COUNTIFS(Overwash_Matrix!$C:$C,1985,Overwash_Matrix!BT:BT,1)) -> 0 | BO5: =IF(COUNTIF(Overwash_Matrix!$C:$C,1985)=0,"",COUNTIFS(Overwash_Matrix!$C:$C,1985,Overwash_Matrix!BU:BU,1)) -> 0 | BP5: =IF(COUNTIF(Overwash_Matrix!$C:$C,1985)=0,"",COUNTIFS(Overwash_Matrix!$C:$C,1985,Overwash_Matrix!BV:BV,1)) -> 0 | BQ5: =IF(COUNTIF(Overwash_Matrix!$C:$C,1985)=0,"",COUNTIFS(Overwash_Matrix!$C:$C,1985,Overwash_Matrix!BW:BW,1)) -> 0 | BR5: =IF(COUNTIF(Overwash_Matrix!$C:$C,1985)=0,"",COUNTIFS(Overwash_Matrix!$C:$C,1985,Overwash_Matrix!BX:BX,1)) -> 0 | BS5: =IF(COUNTIF(Overwash_Matrix!$C:$C,1985)=0,"",COUNTIFS(Overwash_Matrix!$C:$C,1985,Overwash_Matrix!BY:BY,1)) -> 0 | BT5: =IF(COUNTIF(Overwash_Matrix!$C:$C,1985)=0,"",COUNTIFS(Overwash_Matrix!$C:$C,1985,Overwash_Matrix!BZ:BZ,1)) -> 0 | BU5: =IF(COUNTIF(Overwash_Matrix!$C:$C,1985)=0,"",COUNTIFS(Overwash_Matrix!$C:$C,1985,Overwash_Matrix!CA:CA,1)) -> 0 | BV5: =IF(COUNTIF(Overwash_Matrix!$C:$C,1985)=0,"",COUNTIFS(Overwash_Matrix!$C:$C,1985,Overwash_Matrix!CB:CB,1)) -> 0 | BW5: =IF(COUNTIF(Overwash_Matrix!$C:$C,1985)=0,"",COUNTIFS(Overwash_Matrix!$C:$C,1985,Overwash_Matrix!CC:CC,1)) -> 0 | BX5: =IF(COUNTIF(Overwash_Matrix!$C:$C,1985)=0,"",COUNTIFS(Overwash_Matrix!$C:$C,1985,Overwash_Matrix!CD:CD,1)) -> 0 | BY5: =IF(COUNTIF(Overwash_Matrix!$C:$C,1985)=0,"",COUNTIFS(Overwash_Matrix!$C:$C,1985,Overwash_Matrix!CE:CE,1)) -> 0 | BZ5: =IF(COUNTIF(Overwash_Matrix!$C:$C,1985)=0,"",COUNTIFS(Overwash_Matrix!$C:$C,1985,Overwash_Matrix!CF:CF,1)) -> 0 | CA5: =IF(COUNTIF(Overwash_Matrix!$C:$C,1985)=0,"",COUNTIFS(Overwash_Matrix!$C:$C,1985,Overwash_Matrix!CG:CG,1)) -> 0 | CB5: =IF(COUNTIF(Overwash_Matrix!$C:$C,1985)=0,"",COUNTIFS(Overwash_Matrix!$C:$C,1985,Overwash_Matrix!CH:CH,1)) -> 0 | CC5: =IF(COUNTIF(Overwash_Matrix!$C:$C,1985)=0,"",COUNTIFS(Overwash_Matrix!$C:$C,1985,Overwash_Matrix!CI:CI,1)) -> 0 | CD5: =IF(COUNTIF(Overwash_Matrix!$C:$C,1985)=0,"",COUNTIFS(Overwash_Matrix!$C:$C,1985,Overwash_Matrix!CJ:CJ,1)) -> 0 | CE5: =IF(COUNTIF(Overwash_Matrix!$C:$C,1985)=0,"",COUNTIFS(Overwash_Matrix!$C:$C,1985,Overwash_Matrix!CK:CK,1)) -> 0 | CF5: =IF(COUNTIF(Overwash_Matrix!$C:$C,1985)=0,"",COUNTIFS(Overwash_Matrix!$C:$C,1985,Overwash_Matrix!CL:CL,1)) -> 0 | CG5: =IF(COUNTIF(Overwash_Matrix!$C:$C,1985)=0,"",COUNTIFS(Overwash_Matrix!$C:$C,1985,Overwash_Matrix!CM:CM,1)) -> 0 | CH5: =IF(COUNTIF(Overwash_Matrix!$C:$C,1985)=0,"",COUNTIFS(Overwash_Matrix!$C:$C,1985,Overwash_Matrix!CN:CN,1)) -> 0 | CI5: =IF(COUNTIF(Overwash_Matrix!$C:$C,1985)=0,"",COUNTIFS(Overwash_Matrix!$C:$C,1985,Overwash_Matrix!CO:CO,1)) -> 0 | CJ5: =IF(COUNTIF(Overwash_Matrix!$C:$C,1985)=0,"",COUNTIFS(Overwash_Matrix!$C:$C,1985,Overwash_Matrix!CP:CP,1)) -> 0 | CK5: =IF(COUNTIF(Overwash_Matrix!$C:$C,1985)=0,"",COUNTIFS(Overwash_Matrix!$C:$C,1985,Overwash_Matrix!CQ:CQ,1)) -> 0 | CL5: =IF(COUNTIF(Overwash_Matrix!$C:$C,1985)=0,"",COUNTIFS(Overwash_Matrix!$C:$C,1985,Overwash_Matrix!CR:CR,1)) -> 0 | CM5: =IF(COUNTIF(Overwash_Matrix!$C:$C,1985)=0,"",COUNTIFS(Overwash_Matrix!$C:$C,1985,Overwash_Matrix!CS:CS,1)) -> 0 | CN5: =IF(COUNTIF(Overwash_Matrix!$C:$C,1985)=0,"",COUNTIFS(Overwash_Matrix!$C:$C,1985,Overwash_Matrix!CT:CT,1)) -> 0
A6: 1986 | B6: =COUNTIF(Overwash_Matrix!$C:$C,1986) -> 0 | C6: =IF(COUNTIF(Overwash_Matrix!$C:$C,1986)=0,"",COUNTIFS(Overwash_Matrix!$C:$C,1986,Overwash_Matrix!I:I,1)) | D6: =IF(COUNTIF(Overwash_Matrix!$C:$C,1986)=0,"",COUNTIFS(Overwash_Matrix!$C:$C,1986,Overwash_Matrix!J:J,1)) | E6: =IF(COUNTIF(Overwash_Matrix!$C:$C,1986)=0,"",COUNTIFS(Overwash_Matrix!$C:$C,1986,Overwash_Matrix!K:K,1)) | F6: =IF(COUNTIF(Overwash_Matrix!$C:$C,1986)=0,"",COUNTIFS(Overwash_Matrix!$C:$C,1986,Overwash_Matrix!L:L,1)) | G6: =IF(COUNTIF(Overwash_Matrix!$C:$C,1986)=0,"",COUNTIFS(Overwash_Matrix!$C:$C,1986,Overwash_Matrix!M:M,1)) | H6: =IF(COUNTIF(Overwash_Matrix!$C:$C,1986)=0,"",COUNTIFS(Overwash_Matrix!$C:$C,1986,Overwash_Matrix!N:N,1)) | I6: =IF(COUNTIF(Overwash_Matrix!$C:$C,1986)=0,"",COUNTIFS(Overwash_Matrix!$C:$C,1986,Overwash_Matrix!O:O,1)) | J6: =IF(COUNTIF(Overwash_Matrix!$C:$C,1986)=0,"",COUNTIFS(Overwash_Matrix!$C:$C,1986,Overwash_Matrix!P:P,1)) | K6: =IF(COUNTIF(Overwash_Matrix!$C:$C,1986)=0,"",COUNTIFS(Overwash_Matrix!$C:$C,1986,Overwash_Matrix!Q:Q,1)) | L6: =IF(COUNTIF(Overwash_Matrix!$C:$C,1986)=0,"",COUNTIFS(Overwash_Matrix!$C:$C,1986,Overwash_Matrix!R:R,1)) | M6: =IF(COUNTIF(Overwash_Matrix!$C:$C,1986)=0,"",COUNTIFS(Overwash_Matrix!$C:$C,1986,Overwash_Matrix!S:S,1)) | N6: =IF(COUNTIF(Overwash_Matrix!$C:$C,1986)=0,"",COUNTIFS(Overwash_Matrix!$C:$C,1986,Overwash_Matrix!T:T,1)) | O6: =IF(COUNTIF(Overwash_Matrix!$C:$C,1986)=0,"",COUNTIFS(Overwash_Matrix!$C:$C,1986,Overwash_Matrix!U:U,1)) | P6: =IF(COUNTIF(Overwash_Matrix!$C:$C,1986)=0,"",COUNTIFS(Overwash_Matrix!$C:$C,1986,Overwash_Matrix!V:V,1)) | Q6: =IF(COUNTIF(Overwash_Matrix!$C:$C,1986)=0,"",COUNTIFS(Overwash_Matrix!$C:$C,1986,Overwash_Matrix!W:W,1)) | R6: =IF(COUNTIF(Overwash_Matrix!$C:$C,1986)=0,"",COUNTIFS(Overwash_Matrix!$C:$C,1986,Overwash_Matrix!X:X,1)) | S6: =IF(COUNTIF(Overwash_Matrix!$C:$C,1986)=0,"",COUNTIFS(Overwash_Matrix!$C:$C,1986,Overwash_Matrix!Y:Y,1)) | T6: =IF(COUNTIF(Overwash_Matrix!$C:$C,1986)=0,"",COUNTIFS(Overwash_Matrix!$C:$C,1986,Overwash_Matrix!Z:Z,1)) | U6: =IF(COUNTIF(Overwash_Matrix!$C:$C,1986)=0,"",COUNTIFS(Overwash_Matrix!$C:$C,1986,Overwash_Matrix!AA:AA,1)) | V6: =IF(COUNTIF(Overwash_Matrix!$C:$C,1986)=0,"",COUNTIFS(Overwash_Matrix!$C:$C,1986,Overwash_Matrix!AB:AB,1)) | W6: =IF(COUNTIF(Overwash_Matrix!$C:$C,1986)=0,"",COUNTIFS(Overwash_Matrix!$C:$C,1986,Overwash_Matrix!AC:AC,1)) | X6: =IF(COUNTIF(Overwash_Matrix!$C:$C,1986)=0,"",COUNTIFS(Overwash_Matrix!$C:$C,1986,Overwash_Matrix!AD:AD,1)) | Y6: =IF(COUNTIF(Overwash_Matrix!$C:$C,1986)=0,"",COUNTIFS(Overwash_Matrix!$C:$C,1986,Overwash_Matrix!AE:AE,1)) | Z6: =IF(COUNTIF(Overwash_Matrix!$C:$C,1986)=0,"",COUNTIFS(Overwash_Matrix!$C:$C,1986,Overwash_Matrix!AF:AF,1)) | AA6: =IF(COUNTIF(Overwash_Matrix!$C:$C,1986)=0,"",COUNTIFS(Overwash_Matrix!$C:$C,1986,Overwash_Matrix!AG:AG,1)) | AB6: =IF(COUNTIF(Overwash_Matrix!$C:$C,1986)=0,"",COUNTIFS(Overwash_Matrix!$C:$C,1986,Overwash_Matrix!AH:AH,1)) | AC6: =IF(COUNTIF(Overwash_Matrix!$C:$C,1986)=0,"",COUNTIFS(Overwash_Matrix!$C:$C,1986,Overwash_Matrix!AI:AI,1)) | AD6: =IF(COUNTIF(Overwash_Matrix!$C:$C,1986)=0,"",COUNTIFS(Overwash_Matrix!$C:$C,1986,Overwash_Matrix!AJ:AJ,1)) | AE6: =IF(COUNTIF(Overwash_Matrix!$C:$C,1986)=0,"",COUNTIFS(Overwash_Matrix!$C:$C,1986,Overwash_Matrix!AK:AK,1)) | AF6: =IF(COUNTIF(Overwash_Matrix!$C:$C,1986)=0,"",COUNTIFS(Overwash_Matrix!$C:$C,1986,Overwash_Matrix!AL:AL,1)) | AG6: =IF(COUNTIF(Overwash_Matrix!$C:$C,1986)=0,"",COUNTIFS(Overwash_Matrix!$C:$C,1986,Overwash_Matrix!AM:AM,1)) | AH6: =IF(COUNTIF(Overwash_Matrix!$C:$C,1986)=0,"",COUNTIFS(Overwash_Matrix!$C:$C,1986,Overwash_Matrix!AN:AN,1)) | AI6: =IF(COUNTIF(Overwash_Matrix!$C:$C,1986)=0,"",COUNTIFS(Overwash_Matrix!$C:$C,1986,Overwash_Matrix!AO:AO,1)) | AJ6: =IF(COUNTIF(Overwash_Matrix!$C:$C,1986)=0,"",COUNTIFS(Overwash_Matrix!$C:$C,1986,Overwash_Matrix!AP:AP,1)) | AK6: =IF(COUNTIF(Overwash_Matrix!$C:$C,1986)=0,"",COUNTIFS(Overwash_Matrix!$C:$C,1986,Overwash_Matrix!AQ:AQ,1)) | AL6: =IF(COUNTIF(Overwash_Matrix!$C:$C,1986)=0,"",COUNTIFS(Overwash_Matrix!$C:$C,1986,Overwash_Matrix!AR:AR,1)) | AM6: =IF(COUNTIF(Overwash_Matrix!$C:$C,1986)=0,"",COUNTIFS(Overwash_Matrix!$C:$C,1986,Overwash_Matrix!AS:AS,1)) | AN6: =IF(COUNTIF(Overwash_Matrix!$C:$C,1986)=0,"",COUNTIFS(Overwash_Matrix!$C:$C,1986,Overwash_Matrix!AT:AT,1)) | AO6: =IF(COUNTIF(Overwash_Matrix!$C:$C,1986)=0,"",COUNTIFS(Overwash_Matrix!$C:$C,1986,Overwash_Matrix!AU:AU,1)) | AP6: =IF(COUNTIF(Overwash_Matrix!$C:$C,1986)=0,"",COUNTIFS(Overwash_Matrix!$C:$C,1986,Overwash_Matrix!AV:AV,1)) | AQ6: =IF(COUNTIF(Overwash_Matrix!$C:$C,1986)=0,"",COUNTIFS(Overwash_Matrix!$C:$C,1986,Overwash_Matrix!AW:AW,1)) | AR6: =IF(COUNTIF(Overwash_Matrix!$C:$C,1986)=0,"",COUNTIFS(Overwash_Matrix!$C:$C,1986,Overwash_Matrix!AX:AX,1)) | AS6: =IF(COUNTIF(Overwash_Matrix!$C:$C,1986)=0,"",COUNTIFS(Overwash_Matrix!$C:$C,1986,Overwash_Matrix!AY:AY,1)) | AT6: =IF(COUNTIF(Overwash_Matrix!$C:$C,1986)=0,"",COUNTIFS(Overwash_Matrix!$C:$C,1986,Overwash_Matrix!AZ:AZ,1)) | AU6: =IF(COUNTIF(Overwash_Matrix!$C:$C,1986)=0,"",COUNTIFS(Overwash_Matrix!$C:$C,1986,Overwash_Matrix!BA:BA,1)) | AV6: =IF(COUNTIF(Overwash_Matrix!$C:$C,1986)=0,"",COUNTIFS(Overwash_Matrix!$C:$C,1986,Overwash_Matrix!BB:BB,1)) | AW6: =IF(COUNTIF(Overwash_Matrix!$C:$C,1986)=0,"",COUNTIFS(Overwash_Matrix!$C:$C,1986,Overwash_Matrix!BC:BC,1)) | AX6: =IF(COUNTIF(Overwash_Matrix!$C:$C,1986)=0,"",COUNTIFS(Overwash_Matrix!$C:$C,1986,Overwash_Matrix!BD:BD,1)) | AY6: =IF(COUNTIF(Overwash_Matrix!$C:$C,1986)=0,"",COUNTIFS(Overwash_Matrix!$C:$C,1986,Overwash_Matrix!BE:BE,1)) | AZ6: =IF(COUNTIF(Overwash_Matrix!$C:$C,1986)=0,"",COUNTIFS(Overwash_Matrix!$C:$C,1986,Overwash_Matrix!BF:BF,1)) | BA6: =IF(COUNTIF(Overwash_Matrix!$C:$C,1986)=0,"",COUNTIFS(Overwash_Matrix!$C:$C,1986,Overwash_Matrix!BG:BG,1)) | BB6: =IF(COUNTIF(Overwash_Matrix!$C:$C,1986)=0,"",COUNTIFS(Overwash_Matrix!$C:$C,1986,Overwash_Matrix!BH:BH,1)) | BC6: =IF(COUNTIF(Overwash_Matrix!$C:$C,1986)=0,"",COUNTIFS(Overwash_Matrix!$C:$C,1986,Overwash_Matrix!BI:BI,1)) | BD6: =IF(COUNTIF(Overwash_Matrix!$C:$C,1986)=0,"",COUNTIFS(Overwash_Matrix!$C:$C,1986,Overwash_Matrix!BJ:BJ,1)) | BE6: =IF(COUNTIF(Overwash_Matrix!$C:$C,1986)=0,"",COUNTIFS(Overwash_Matrix!$C:$C,1986,Overwash_Matrix!BK:BK,1)) | BF6: =IF(COUNTIF(Overwash_Matrix!$C:$C,1986)=0,"",COUNTIFS(Overwash_Matrix!$C:$C,1986,Overwash_Matrix!BL:BL,1)) | BG6: =IF(COUNTIF(Overwash_Matrix!$C:$C,1986)=0,"",COUNTIFS(Overwash_Matrix!$C:$C,1986,Overwash_Matrix!BM:BM,1)) | BH6: =IF(COUNTIF(Overwash_Matrix!$C:$C,1986)=0,"",COUNTIFS(Overwash_Matrix!$C:$C,1986,Overwash_Matrix!BN:BN,1)) | BI6: =IF(COUNTIF(Overwash_Matrix!$C:$C,1986)=0,"",COUNTIFS(Overwash_Matrix!$C:$C,1986,Overwash_Matrix!BO:BO,1)) | BJ6: =IF(COUNTIF(Overwash_Matrix!$C:$C,1986)=0,"",COUNTIFS(Overwash_Matrix!$C:$C,1986,Overwash_Matrix!BP:BP,1)) | BK6: =IF(COUNTIF(Overwash_Matrix!$C:$C,1986)=0,"",COUNTIFS(Overwash_Matrix!$C:$C,1986,Overwash_Matrix!BQ:BQ,1)) | BL6: =IF(COUNTIF(Overwash_Matrix!$C:$C,1986)=0,"",COUNTIFS(Overwash_Matrix!$C:$C,1986,Overwash_Matrix!BR:BR,1)) | BM6: =IF(COUNTIF(Overwash_Matrix!$C:$C,1986)=0,"",COUNTIFS(Overwash_Matrix!$C:$C,1986,Overwash_Matrix!BS:BS,1)) | BN6: =IF(COUNTIF(Overwash_Matrix!$C:$C,1986)=0,"",COUNTIFS(Overwash_Matrix!$C:$C,1986,Overwash_Matrix!BT:BT,1)) | BO6: =IF(COUNTIF(Overwash_Matrix!$C:$C,1986)=0,"",COUNTIFS(Overwash_Matrix!$C:$C,1986,Overwash_Matrix!BU:BU,1)) | BP6: =IF(COUNTIF(Overwash_Matrix!$C:$C,1986)=0,"",COUNTIFS(Overwash_Matrix!$C:$C,1986,Overwash_Matrix!BV:BV,1)) | BQ6: =IF(COUNTIF(Overwash_Matrix!$C:$C,1986)=0,"",COUNTIFS(Overwash_Matrix!$C:$C,1986,Overwash_Matrix!BW:BW,1)) | BR6: =IF(COUNTIF(Overwash_Matrix!$C:$C,1986)=0,"",COUNTIFS(Overwash_Matrix!$C:$C,1986,Overwash_Matrix!BX:BX,1)) | BS6: =IF(COUNTIF(Overwash_Matrix!$C:$C,1986)=0,"",COUNTIFS(Overwash_Matrix!$C:$C,1986,Overwash_Matrix!BY:BY,1)) | BT6: =IF(COUNTIF(Overwash_Matrix!$C:$C,1986)=0,"",COUNTIFS(Overwash_Matrix!$C:$C,1986,Overwash_Matrix!BZ:BZ,1)) | BU6: =IF(COUNTIF(Overwash_Matrix!$C:$C,1986)=0,"",COUNTIFS(Overwash_Matrix!$C:$C,1986,Overwash_Matrix!CA:CA,1)) | BV6: =IF(COUNTIF(Overwash_Matrix!$C:$C,1986)=0,"",COUNTIFS(Overwash_Matrix!$C:$C,1986,Overwash_Matrix!CB:CB,1)) | BW6: =IF(COUNTIF(Overwash_Matrix!$C:$C,1986)=0,"",COUNTIFS(Overwash_Matrix!$C:$C,1986,Overwash_Matrix!CC:CC,1)) | BX6: =IF(COUNTIF(Overwash_Matrix!$C:$C,1986)=0,"",COUNTIFS(Overwash_Matrix!$C:$C,1986,Overwash_Matrix!CD:CD,1)) | BY6: =IF(COUNTIF(Overwash_Matrix!$C:$C,1986)=0,"",COUNTIFS(Overwash_Matrix!$C:$C,1986,Overwash_Matrix!CE:CE,1)) | BZ6: =IF(COUNTIF(Overwash_Matrix!$C:$C,1986)=0,"",COUNTIFS(Overwash_Matrix!$C:$C,1986,Overwash_Matrix!CF:CF,1)) | CA6: =IF(COUNTIF(Overwash_Matrix!$C:$C,1986)=0,"",COUNTIFS(Overwash_Matrix!$C:$C,1986,Overwash_Matrix!CG:CG,1)) | CB6: =IF(COUNTIF(Overwash_Matrix!$C:$C,1986)=0,"",COUNTIFS(Overwash_Matrix!$C:$C,1986,Overwash_Matrix!CH:CH,1)) | CC6: =IF(COUNTIF(Overwash_Matrix!$C:$C,1986)=0,"",COUNTIFS(Overwash_Matrix!$C:$C,1986,Overwash_Matrix!CI:CI,1)) | CD6: =IF(COUNTIF(Overwash_Matrix!$C:$C,1986)=0,"",COUNTIFS(Overwash_Matrix!$C:$C,1986,Overwash_Matrix!CJ:CJ,1)) | CE6: =IF(COUNTIF(Overwash_Matrix!$C:$C,1986)=0,"",COUNTIFS(Overwash_Matrix!$C:$C,1986,Overwash_Matrix!CK:CK,1)) | CF6: =IF(COUNTIF(Overwash_Matrix!$C:$C,1986)=0,"",COUNTIFS(Overwash_Matrix!$C:$C,1986,Overwash_Matrix!CL:CL,1)) | CG6: =IF(COUNTIF(Overwash_Matrix!$C:$C,1986)=0,"",COUNTIFS(Overwash_Matrix!$C:$C,1986,Overwash_Matrix!CM:CM,1)) | CH6: =IF(COUNTIF(Overwash_Matrix!$C:$C,1986)=0,"",COUNTIFS(Overwash_Matrix!$C:$C,1986,Overwash_Matrix!CN:CN,1)) | CI6: =IF(COUNTIF(Overwash_Matrix!$C:$C,1986)=0,"",COUNTIFS(Overwash_Matrix!$C:$C,1986,Overwash_Matrix!CO:CO,1)) | CJ6: =IF(COUNTIF(Overwash_Matrix!$C:$C,1986)=0,"",COUNTIFS(Overwash_Matrix!$C:$C,1986,Overwash_Matrix!CP:CP,1)) | CK6: =IF(COUNTIF(Overwash_Matrix!$C:$C,1986)=0,"",COUNTIFS(Overwash_Matrix!$C:$C,1986,Overwash_Matrix!CQ:CQ,1)) | CL6: =IF(COUNTIF(Overwash_Matrix!$C:$C,1986)=0,"",COUNTIFS(Overwash_Matrix!$C:$C,1986,Overwash_Matrix!CR:CR,1)) | CM6: =IF(COUNTIF(Overwash_Matrix!$C:$C,1986)=0,"",COUNTIFS(Overwash_Matrix!$C:$C,1986,Overwash_Matrix!CS:CS,1)) | CN6: =IF(COUNTIF(Overwash_Matrix!$C:$C,1986)=0,"",COUNTIFS(Overwash_Matrix!$C:$C,1986,Overwash_Matrix!CT:CT,1))
